Workbook

Sheet Dashboard
A1: Engineering Activity Dashboard | N1: Name (helper) | O1: Team | P1: PRs | Q1: LoC
A2: Period: May 1 – Jun 10, 2026 (6 weekly snapshots) • Source: Data tab, 34 active named engineers • Ranked by PRs merged | N2: {=_xlfn._xlws.FILTER(Data!A3:A39,Data!L3:L39<>"")} -> Anthony Anderson | O2: {=_xlfn._xlws.FILTER(Data!C3:C39,Data!L3:L39<>"")} -> Engineering Leadership | P2: {=_xlfn._xlws.FILTER(Data!AE3:AE39,Data!L3:L39<>"")} -> 3 | Q2: {=_xlfn._xlws.FILTER(Data!AG3:AG39,Data!L3:L39<>"")} -> 1529
A3: IMPORTANT THIS IS USING PRS FOR RANKING IT A WORK IN PROGESS | N3: Asa Baylus | O3: Engineering Leadership | P3: 9 | Q3: 50491
N4: Jonathan Umscheid | O4: Engineering Leadership | P4: 9 | Q4: 33593
A5: 1 · Team Summary | N5: Chris Bown | O5: Engineering Leadership | P5: 178 | Q5: 116798
A6: Team | B6: Total PRs | C6: % of PRs | D6: Total LoC | E6: % of LoC | F6: Headcount | N6: Andy Robins | O6: Labs | P6: 0 | Q6: 3418
A7: Engineering Leadership | B7: =SUMIF(Data!$C$3:$C$39,$A7,Data!$AE$3:$AE$39) -> 199 | C7: =B7/$B$12 -> 0.21329046 | D7: =SUMIF(Data!$C$3:$C$39,$A7,Data!$AG$3:$AG$39) -> 202411 | E7: =D7/$D$12 -> 0.041590734 | F7: =COUNTIFS(Data!$C$3:$C$39,$A7,Data!$L$3:$L$39,"<>") -> 4 | N7: Don Porter | O7: Labs | P7: 0 | Q7: 198208
A8: Labs | B8: =SUMIF(Data!$C$3:$C$39,$A8,Data!$AE$3:$AE$39) -> 62 | C8: =B8/$B$12 -> 0.066452304 | D8: =SUMIF(Data!$C$3:$C$39,$A8,Data!$AG$3:$AG$39) -> 1519078 | E8: =D8/$D$12 -> 0.31213506 | F8: =COUNTIFS(Data!$C$3:$C$39,$A8,Data!$L$3:$L$39,"<>") -> 5 | N8: Francisco Micucci | O8: Labs | P8: 39 | Q8: 37507
A9: Platform | B9: =SUMIF(Data!$C$3:$C$39,$A9,Data!$AE$3:$AE$39) -> 174 | C9: =B9/$B$12 -> 0.18649518 | D9: =SUMIF(Data!$C$3:$C$39,$A9,Data!$AG$3:$AG$39) -> 31145 | E9: =D9/$D$12 -> 0.0063995703 | F9: =COUNTIFS(Data!$C$3:$C$39,$A9,Data!$L$3:$L$39,"<>") -> 4 | N9: Eric Spieguel | O9: Labs | P9: 1 | Q9: 18176
A10: Core | B10: =SUMIF(Data!$C$3:$C$39,$A10,Data!$AE$3:$AE$39) -> 495 | C10: =B10/$B$12 -> 0.53054662 | D10: =SUMIF(Data!$C$3:$C$39,$A10,Data!$AG$3:$AG$39) -> 3106834 | E10: =D10/$D$12 -> 0.63838185 | F10: =COUNTIFS(Data!$C$3:$C$39,$A10,Data!$L$3:$L$39,"<>") -> 20 | N10: Juan Oliu | O10: Labs | P10: 22 | Q10: 1261769
A11: Technical Support | B11: =SUMIF(Data!$C$3:$C$39,$A11,Data!$AE$3:$AE$39) -> 3 | C11: =B11/$B$12 -> 0.0032154341 | D11: =SUMIF(Data!$C$3:$C$39,$A11,Data!$AG$3:$AG$39) -> 7265 | E11: =D11/$D$12 -> 0.0014927879 | F11: =COUNTIFS(Data!$C$3:$C$39,$A11,Data!$L$3:$L$39,"<>") -> 1 | N11: Aaron Entwistle | O11: Platform | P11: 64 | Q11: 12408
A12: Total | B12: =SUM(B7:B11) -> 933 | C12: =SUM(C7:C11) -> 1 | D12: =SUM(D7:D11) -> 4866733 | E12: =SUM(E7:E11) -> 1 | F12: =SUM(F7:F11) -> 34 | N12: Anisah Reed | O12: Platform | P12: 5 | Q12: 6005
N13: Zach Ward | O13: Platform | P13: 100 | Q13: 12621
A14: 2 · Top 10 Contributors (by PRs merged) | G14: 3 · Lowest 10 Contributors (active engineers) | N14: Kyle Snyder | O14: Platform | P14: 5 | Q14: 111
A15: # | B15: Name | C15: PRs | D15: LoC | E15: Team | G15: # | H15: Name | I15: PRs | J15: LoC | K15: Team | N15: Antonio Pola | O15: Core | P15: 13 | Q15: 7110
A16: {=_xlfn.SEQUENCE(10)} -> 1 | B16: {=_xlfn.TAKE(_xlfn.SORTBY(_xlfn.ANCHORARRAY($N$2),_xlfn.ANCHORARRAY($P$2),-1),10)} -> Chris Bown | C16: {=_xlfn.TAKE(_xlfn.SORTBY(_xlfn.ANCHORARRAY($P$2),_xlfn.ANCHORARRAY($P$2),-1),10)} -> 178 | D16: {=_xlfn.TAKE(_xlfn.SORTBY(_xlfn.ANCHORARRAY($Q$2),_xlfn.ANCHORARRAY($P$2),-1),10)} -> 116798 | E16: {=_xlfn.TAKE(_xlfn.SORTBY(_xlfn.ANCHORARRAY($O$2),_xlfn.ANCHORARRAY($P$2),-1),10)} -> Engineering Leadership | G16: {=_xlfn.SEQUENCE(10)} -> 1 | H16: {=_xlfn.TAKE(_xlfn.SORTBY(_xlfn.ANCHORARRAY($N$2),_xlfn.ANCHORARRAY($P$2),1),10)} -> Andy Robins | I16: {=_xlfn.TAKE(_xlfn.SORTBY(_xlfn.ANCHORARRAY($P$2),_xlfn.ANCHORARRAY($P$2),1),10)} -> 0 | J16: {=_xlfn.TAKE(_xlfn.SORTBY(_xlfn.ANCHORARRAY($Q$2),_xlfn.ANCHORARRAY($P$2),1),10)} -> 3418 | K16: {=_xlfn.TAKE(_xlfn.SORTBY(_xlfn.ANCHORARRAY($O$2),_xlfn.ANCHORARRAY($P$2),1),10)} -> Labs | N16: Adrian Castillo | O16: Core | P16: 30 | Q16: 93830
A17: 2 | B17: Zach Ward | C17: 100 | D17: 12621 | E17: Platform | G17: 2 | H17: Don Porter | I17: 0 | J17: 198208 | K17: Labs | N17: Matt Duffy | O17: Core | P17: 28 | Q17: 15020
A18: 3 | B18: Aaron Entwistle | C18: 64 | D18: 12408 | E18: Platform | G18: 3 | H18: Murat Ozel | I18: 0 | J18: 30 | K18: Core | N18: Hector Tinajero | O18: Core | P18: 6 | Q18: 1628
A19: 4 | B19: David Rozen | C19: 62 | D19: 45942 | E19: Core | G19: 4 | H19: Eric Spieguel | I19: 1 | J19: 18176 | K19: Labs | N19: David Rozen | O19: Core | P19: 62 | Q19: 45942
A20: 5 | B20: Tomas Gorkin | C20: 61 | D20: 128000 | E20: Core | G20: 5 | H20: Bruce Vaughn | I20: 2 | J20: 1320 | K20: Core | N20: Ryan Trimble | O20: Core | P20: 27 | Q20: 51229
A21: 6 | B21: Joe Hosman | C21: 50 | D21: 128300 | E21: Core | G21: 6 | H21: Anthony Anderson | I21: 3 | J21: 1529 | K21: Engineering Leadership | N21: Maaz Qureshi | O21: Core | P21: 24 | Q21: 24497
A22: 7 | B22: Fernando Bastos | C22: 41 | D22: 37364 | E22: Core | G22: 7 | H22: Skylar Ryals | I22: 3 | J22: 7265 | K22: Technical Support | N22: Ahmed Sohail | O22: Core | P22: 17 | Q22: 20966
A23: 8 | B23: Steve Rives | C23: 40 | D23: 25480 | E23: Core | G23: 8 | H23: Chris Cavazos | I23: 4 | J23: 547 | K23: Core | N23: Joe Hosman | O23: Core | P23: 50 | Q23: 128300
A24: 9 | B24: Francisco Micucci | C24: 39 | D24: 37507 | E24: Labs | G24: 9 | H24: Anisah Reed | I24: 5 | J24: 6005 | K24: Platform | N24: Ignacio Harretche | O24: Core | P24: 17 | Q24: 5253
A25: 10 | B25: Anthony Lehenbauer | C25: 31 | D25: 2084495 | E25: Core | G25: 10 | H25: Kyle Snyder | I25: 5 | J25: 111 | K25: Platform | N25: Steve Rives | O25: Core | P25: 40 | Q25: 25480
N26: Fernando Bastos | O26: Core | P26: 41 | Q26: 37364
A27: 4 · Trends Over Time | N27: Anthony Lehenbauer | O27: Core | P27: 31 | Q27: 2084495
A28: Weekly totals across all active engineers. Note: LoC is highly volatile due to bulk/generated-code commits — read PRs as the stable signal. | N28: Lautaro Araujo | O28: Core | P28: 17 | Q28: 23982
A29: Metric | B29: May 1–8 | C29: May 8–15 | D29: May 15–22 | E29: May 22–29 | F29: May 29–Jun 5 | G29: Jun 5–10 | N29: Martin Ferreira | O29: Core | P29: 6 | Q29: 408252
A30: Total PRs | B30: =SUM(Data!M3:M39) -> 205 | C30: =SUM(Data!P3:P39) -> 180 | D30: =SUM(Data!S3:S39) -> 123 | E30: =SUM(Data!V3:V39) -> 153 | F30: =SUM(Data!Y3:Y39) -> 147 | G30: =SUM(Data!AB3:AB39) -> 125 | N30: Tomas Gorkin | O30: Core | P30: 61 | Q30: 128000
A31: Total LoC | B31: =SUM(Data!O3:O39) -> 1118510 | C31: =SUM(Data!R3:R39) -> 318252 | D31: =SUM(Data!U3:U39) -> 2327347 | E31: =SUM(Data!X3:X39) -> 493652 | F31: =SUM(Data!AA3:AA39) -> 269052 | G31: =SUM(Data!AD3:AD39) -> 339920 | N31: Bruce Vaughn | O31: Core | P31: 2 | Q31: 1320
A32: Active (PRs>0) | B32: =COUNTIF(Data!M3:M39,">0") -> 19 | C32: =COUNTIF(Data!P3:P39,">0") -> 24 | D32: =COUNTIF(Data!S3:S39,">0") -> 21 | E32: =COUNTIF(Data!V3:V39,">0") -> 24 | F32: =COUNTIF(Data!Y3:Y39,">0") -> 26 | G32: =COUNTIF(Data!AB3:AB39,">0") -> 25 | N32: Murat Ozel | O32: Core | P32: 0 | Q32: 30
N33: Glenn Holmes | O33: Core | P33: 19 | Q33: 3589
A34: Weekly PRs by team | N34: Chris Cavazos | O34: Core | P34: 4 | Q34: 547
A35: Team | B35: =B29 -> May 1–8 | C35: =C29 -> May 8–15 | D35: =D29 -> May 15–22 | E35: =E29 -> May 22–29 | F35: =F29 -> May 29–Jun 5 | G35: =G29 -> Jun 5–10 | N35: Skylar Ryals | O35: Technical Support | P35: 3 | Q35: 7265
A36: Engineering Leadership | B36: =SUMIF(Data!$C$3:$C$39,$A36,Data!M$3:M$39) -> 102 | C36: =SUMIF(Data!$C$3:$C$39,$A36,Data!P$3:P$39) -> 34 | D36: =SUMIF(Data!$C$3:$C$39,$A36,Data!S$3:S$39) -> 16 | E36: =SUMIF(Data!$C$3:$C$39,$A36,Data!V$3:V$39) -> 11 | F36: =SUMIF(Data!$C$3:$C$39,$A36,Data!Y$3:Y$39) -> 22 | G36: =SUMIF(Data!$C$3:$C$39,$A36,Data!AB$3:AB$39) -> 14
A37: Labs | B37: =SUMIF(Data!$C$3:$C$39,$A37,Data!M$3:M$39) -> 7 | C37: =SUMIF(Data!$C$3:$C$39,$A37,Data!P$3:P$39) -> 17 | D37: =SUMIF(Data!$C$3:$C$39,$A37,Data!S$3:S$39) -> 15 | E37: =SUMIF(Data!$C$3:$C$39,$A37,Data!V$3:V$39) -> 4 | F37: =SUMIF(Data!$C$3:$C$39,$A37,Data!Y$3:Y$39) -> 12 | G37: =SUMIF(Data!$C$3:$C$39,$A37,Data!AB$3:AB$39) -> 7
A38: Platform | B38: =SUMIF(Data!$C$3:$C$39,$A38,Data!M$3:M$39) -> 16 | C38: =SUMIF(Data!$C$3:$C$39,$A38,Data!P$3:P$39) -> 43 | D38: =SUMIF(Data!$C$3:$C$39,$A38,Data!S$3:S$39) -> 37 | E38: =SUMIF(Data!$C$3:$C$39,$A38,Data!V$3:V$39) -> 29 | F38: =SUMIF(Data!$C$3:$C$39,$A38,Data!Y$3:Y$39) -> 21 | G38: =SUMIF(Data!$C$3:$C$39,$A38,Data!AB$3:AB$39) -> 28
A39: Core | B39: =SUMIF(Data!$C$3:$C$39,$A39,Data!M$3:M$39) -> 80 | C39: =SUMIF(Data!$C$3:$C$39,$A39,Data!P$3:P$39) -> 85 | D39: =SUMIF(Data!$C$3:$C$39,$A39,Data!S$3:S$39) -> 55 | E39: =SUMIF(Data!$C$3:$C$39,$A39,Data!V$3:V$39) -> 109 | F39: =SUMIF(Data!$C$3:$C$39,$A39,Data!Y$3:Y$39) -> 91 | G39: =SUMIF(Data!$C$3:$C$39,$A39,Data!AB$3:AB$39) -> 75
A40: Technical Support | B40: =SUMIF(Data!$C$3:$C$39,$A40,Data!M$3:M$39) -> 0 | C40: =SUMIF(Data!$C$3:$C$39,$A40,Data!P$3:P$39) -> 1 | D40: =SUMIF(Data!$C$3:$C$39,$A40,Data!S$3:S$39) -> 0 | E40: =SUMIF(Data!$C$3:$C$39,$A40,Data!V$3:V$39) -> 0 | F40: =SUMIF(Data!$C$3:$C$39,$A40,Data!Y$3:Y$39) -> 1 | G40: =SUMIF(Data!$C$3:$C$39,$A40,Data!AB$3:AB$39) -> 1
...

Sheet Data (2)
A1: Full Name | B1: Title | C1: Team | D1: Workstream | E1: Manager | F1: Employment Type | G1: Company | H1: Location | I1: Discipline | J1: Role | K1: Seniority | L1: GitHub Account | M1: May 1–8 | P1: May 8–15 | S1: May 15–22 | V1: May 22–29 | Y1: May 29–Jun 5 | AB1: Jun 5–10 | AE1: Total | AH1: Notes
M2: PR | N2: Tickets | O2: LoC | P2: PR | Q2: Tickets | R2: LoC | S2: PR | T2: Tickets | U2: LoC | V2: PR | W2: Tickets | X2: LoC | Y2: PR | Z2: Tickets | AA2: LoC | AB2: PR | AC2: Tickets | AD2: LoC | AE2: PR | AF2: Tickets | AG2: LoC
A3: Anthony Anderson | B3: Interim Director of Engineering | C3: Engineering Leadership | D3: Admin | E3: Annu Singh | F3: FTE | G3: Stratus | H3: Orlando | I3: Leadership | J3: Other | K3: Director | L3: anthonyagtp | M3: =IF($L3="","",SUMIF(#REF!,$L3,#REF!)) -> #REF! | O3: =IF($L3="","",SUMIF(#REF!,$L3,#REF!)) -> #REF! | P3: =IF($L3="","",SUMIF(#REF!,$L3,#REF!)) -> #REF! | R3: =IF($L3="","",SUMIF(#REF!,$L3,#REF!)) -> #REF! | S3: =IF($L3="","",SUMIF(#REF!,$L3,#REF!)) -> #REF! | U3: =IF($L3="","",SUMIF(#REF!,$L3,#REF!)) -> #REF! | V3: =IF($L3="","",SUMIF(#REF!,$L3,#REF!)) -> #REF! | X3: =IF($L3="","",SUMIF(#REF!,$L3,#REF!)) -> #REF! | Y3: =IF($L3="","",SUMIF(#REF!,$L3,#REF!)) -> #REF! | AA3: =IF($L3="","",SUMIF(#REF!,$L3,#REF!)) -> #REF! | AB3: =IF($L3="","",SUMIF(#REF!,$L3,#REF!)) -> #REF! | AD3: =IF($L3="","",SUMIF(#REF!,$L3,#REF!)) -> #REF! | AE3: =IF($L3="","",SUMIF(#REF!,$L3,#REF!)) -> #REF! | AG3: =IF($L3="","",SUMIF(#REF!,$L3,#REF!)) -> #REF!
A4: Asa Baylus | B4: VP Engineering | C4: Engineering Leadership | D4: Admin | E4: Annu Singh | F4: FTE | G4: Stratus | H4: Virginia | I4: Leadership | J4: Other | K4: Director | L4: asabaylus | M4: =IF($L4="","",SUMIF(#REF!,$L4,#REF!)) -> #REF! | O4: =IF($L4="","",SUMIF(#REF!,$L4,#REF!)) -> #REF! | P4: =IF($L4="","",SUMIF(#REF!,$L4,#REF!)) -> #REF! | R4: =IF($L4="","",SUMIF(#REF!,$L4,#REF!)) -> #REF! | S4: =IF($L4="","",SUMIF(#REF!,$L4,#REF!)) -> #REF! | U4: =IF($L4="","",SUMIF(#REF!,$L4,#REF!)) -> #REF! | V4: =IF($L4="","",SUMIF(#REF!,$L4,#REF!)) -> #REF! | X4: =IF($L4="","",SUMIF(#REF!,$L4,#REF!)) -> #REF! | Y4: =IF($L4="","",SUMIF(#REF!,$L4,#REF!)) -> #REF! | AA4: =IF($L4="","",SUMIF(#REF!,$L4,#REF!)) -> #REF! | AB4: =IF($L4="","",SUMIF(#REF!,$L4,#REF!)) -> #REF! | AD4: =IF($L4="","",SUMIF(#REF!,$L4,#REF!)) -> #REF! | AE4: =IF($L4="","",SUMIF(#REF!,$L4,#REF!)) -> #REF! | AG4: =IF($L4="","",SUMIF(#REF!,$L4,#REF!)) -> #REF!
A5: Jonathan Umscheid | B5: Chief Innovation Officer | C5: Engineering Leadership | D5: Admin | E5: Annu Singh | F5: FTE | G5: Stratus | H5: North Carolina | I5: Leadership | J5: Other | K5: Director | L5: jonathanumscheid | M5: =IF($L5="","",SUMIF(#REF!,$L5,#REF!)) -> #REF! | O5: =IF($L5="","",SUMIF(#REF!,$L5,#REF!)) -> #REF! | P5: =IF($L5="","",SUMIF(#REF!,$L5,#REF!)) -> #REF! | R5: =IF($L5="","",SUMIF(#REF!,$L5,#REF!)) -> #REF! | S5: =IF($L5="","",SUMIF(#REF!,$L5,#REF!)) -> #REF! | U5: =IF($L5="","",SUMIF(#REF!,$L5,#REF!)) -> #REF! | V5: =IF($L5="","",SUMIF(#REF!,$L5,#REF!)) -> #REF! | X5: =IF($L5="","",SUMIF(#REF!,$L5,#REF!)) -> #REF! | Y5: =IF($L5="","",SUMIF(#REF!,$L5,#REF!)) -> #REF! | AA5: =IF($L5="","",SUMIF(#REF!,$L5,#REF!)) -> #REF! | AB5: =IF($L5="","",SUMIF(#REF!,$L5,#REF!)) -> #REF! | AD5: =IF($L5="","",SUMIF(#REF!,$L5,#REF!)) -> #REF! | AE5: =IF($L5="","",SUMIF(#REF!,$L5,#REF!)) -> #REF! | AG5: =IF($L5="","",SUMIF(#REF!,$L5,#REF!)) -> #REF!
A6: Crystal Ross | B6: Director Technical Support | C6: Engineering Leadership | D6: Admin | E6: Annu Singh | F6: FTE | G6: Stratus | H6: Massachusetts | I6: Leadership | J6: Other | K6: Director | M6: =IF($L6="","",SUMIF(#REF!,$L6,#REF!)) | O6: =IF($L6="","",SUMIF(#REF!,$L6,#REF!)) | P6: =IF($L6="","",SUMIF(#REF!,$L6,#REF!)) | R6: =IF($L6="","",SUMIF(#REF!,$L6,#REF!)) | S6: =IF($L6="","",SUMIF(#REF!,$L6,#REF!)) | U6: =IF($L6="","",SUMIF(#REF!,$L6,#REF!)) | V6: =IF($L6="","",SUMIF(#REF!,$L6,#REF!)) | X6: =IF($L6="","",SUMIF(#REF!,$L6,#REF!)) | Y6: =IF($L6="","",SUMIF(#REF!,$L6,#REF!)) | AA6: =IF($L6="","",SUMIF(#REF!,$L6,#REF!)) | AB6: =IF($L6="","",SUMIF(#REF!,$L6,#REF!)) | AD6: =IF($L6="","",SUMIF(#REF!,$L6,#REF!)) | AE6: =IF($L6="","",SUMIF(#REF!,$L6,#REF!)) | AG6: =IF($L6="","",SUMIF(#REF!,$L6,#REF!))
A7: Chris Bown | B7: Senior Director, Platform Engineering | C7: Engineering Leadership | D7: Admin | E7: Annu Singh | F7: FTE | G7: Stratus | H7: Phoenix | I7: Leadership | J7: Developer | K7: Director | L7: cbown75 | M7: =IF($L7="","",SUMIF(#REF!,$L7,#REF!)) -> #REF! | O7: =IF($L7="","",SUMIF(#REF!,$L7,#REF!)) -> #REF! | P7: =IF($L7="","",SUMIF(#REF!,$L7,#REF!)) -> #REF! | R7: =IF($L7="","",SUMIF(#REF!,$L7,#REF!)) -> #REF! | S7: =IF($L7="","",SUMIF(#REF!,$L7,#REF!)) -> #REF! | U7: =IF($L7="","",SUMIF(#REF!,$L7,#REF!)) -> #REF! | V7: =IF($L7="","",SUMIF(#REF!,$L7,#REF!)) -> #REF! | X7: =IF($L7="","",SUMIF(#REF!,$L7,#REF!)) -> #REF! | Y7: =IF($L7="","",SUMIF(#REF!,$L7,#REF!)) -> #REF! | AA7: =IF($L7="","",SUMIF(#REF!,$L7,#REF!)) -> #REF! | AB7: =IF($L7="","",SUMIF(#REF!,$L7,#REF!)) -> #REF! | AD7: =IF($L7="","",SUMIF(#REF!,$L7,#REF!)) -> #REF! | AE7: =IF($L7="","",SUMIF(#REF!,$L7,#REF!)) -> #REF! | AG7: =IF($L7="","",SUMIF(#REF!,$L7,#REF!)) -> #REF!
A8: Andy Robins | B8: Full Stack Engineer | C8: Labs | D8: {=IFERROR(_xlfn.TEXTJOIN(", ",TRUE,_xlfn.UNIQUE(_xlfn._xlws.FILTER(#REF!,(#REF!="Final")*(COUNTIFS('[1]Demand Capacity'!$B:$B,$A8,'[1]Demand Capacity'!$A:$A,#REF!)>0),""))),"")} | E8: Jonathan Umscheid | F8: FTE | G8: Stratus | H8: UK | I8: Full Stack | J8: Developer | K8: Lead | L8: andyrobins-gtp | M8: =IF($L8="","",SUMIF(#REF!,$L8,#REF!)) -> #REF! | O8: =IF($L8="","",SUMIF(#REF!,$L8,#REF!)) -> #REF! | P8: =IF($L8="","",SUMIF(#REF!,$L8,#REF!)) -> #REF! | R8: =IF($L8="","",SUMIF(#REF!,$L8,#REF!)) -> #REF! | S8: =IF($L8="","",SUMIF(#REF!,$L8,#REF!)) -> #REF! | U8: =IF($L8="","",SUMIF(#REF!,$L8,#REF!)) -> #REF! | V8: =IF($L8="","",SUMIF(#REF!,$L8,#REF!)) -> #REF! | X8: =IF($L8="","",SUMIF(#REF!,$L8,#REF!)) -> #REF! | Y8: =IF($L8="","",SUMIF(#REF!,$L8,#REF!)) -> #REF! | AA8: =IF($L8="","",SUMIF(#REF!,$L8,#REF!)) -> #REF! | AB8: =IF($L8="","",SUMIF(#REF!,$L8,#REF!)) -> #REF! | AD8: =IF($L8="","",SUMIF(#REF!,$L8,#REF!)) -> #REF! | AE8: =IF($L8="","",SUMIF(#REF!,$L8,#REF!)) -> #REF! | AG8: =IF($L8="","",SUMIF(#REF!,$L8,#REF!)) -> #REF!
A9: Don Porter | B9: Full Stack Engineer | C9: Labs | D9: {=IFERROR(_xlfn.TEXTJOIN(", ",TRUE,_xlfn.UNIQUE(_xlfn._xlws.FILTER(#REF!,(#REF!="Final")*(COUNTIFS('[1]Demand Capacity'!$B:$B,$A9,'[1]Demand Capacity'!$A:$A,#REF!)>0),""))),"")} | E9: Jonathan Umscheid | F9: FTE | G9: Stratus | H9: Columbia | I9: Full Stack | J9: Developer | K9: Senior | L9: donatgtp | M9: =IF($L9="","",SUMIF(#REF!,$L9,#REF!)) -> #REF! | O9: =IF($L9="","",SUMIF(#REF!,$L9,#REF!)) -> #REF! | P9: =IF($L9="","",SUMIF(#REF!,$L9,#REF!)) -> #REF! | R9: =IF($L9="","",SUMIF(#REF!,$L9,#REF!)) -> #REF! | S9: =IF($L9="","",SUMIF(#REF!,$L9,#REF!)) -> #REF! | U9: =IF($L9="","",SUMIF(#REF!,$L9,#REF!)) -> #REF! | V9: =IF($L9="","",SUMIF(#REF!,$L9,#REF!)) -> #REF! | X9: =IF($L9="","",SUMIF(#REF!,$L9,#REF!)) -> #REF! | Y9: =IF($L9="","",SUMIF(#REF!,$L9,#REF!)) -> #REF! | AA9: =IF($L9="","",SUMIF(#REF!,$L9,#REF!)) -> #REF! | AB9: =IF($L9="","",SUMIF(#REF!,$L9,#REF!)) -> #REF! | AD9: =IF($L9="","",SUMIF(#REF!,$L9,#REF!)) -> #REF! | AE9: =IF($L9="","",SUMIF(#REF!,$L9,#REF!)) -> #REF! | AG9: =IF($L9="","",SUMIF(#REF!,$L9,#REF!)) -> #REF!
A10: Francisco Micucci | B10: Full Stack Engineer | C10: Labs | D10: {=IFERROR(_xlfn.TEXTJOIN(", ",TRUE,_xlfn.UNIQUE(_xlfn._xlws.FILTER(#REF!,(#REF!="Final")*(COUNTIFS('[1]Demand Capacity'!$B:$B,$A10,'[1]Demand Capacity'!$A:$A,#REF!)>0),""))),"")} | E10: Asa Baylus | F10: Contractor | G10: Marvik | I10: Full Stack | J10: Developer | K10: Senior | L10: famicucci | M10: =IF($L10="","",SUMIF(#REF!,$L10,#REF!)) -> #REF! | O10: =IF($L10="","",SUMIF(#REF!,$L10,#REF!)) -> #REF! | P10: =IF($L10="","",SUMIF(#REF!,$L10,#REF!)) -> #REF! | R10: =IF($L10="","",SUMIF(#REF!,$L10,#REF!)) -> #REF! | S10: =IF($L10="","",SUMIF(#REF!,$L10,#REF!)) -> #REF! | U10: =IF($L10="","",SUMIF(#REF!,$L10,#REF!)) -> #REF! | V10: =IF($L10="","",SUMIF(#REF!,$L10,#REF!)) -> #REF! | X10: =IF($L10="","",SUMIF(#REF!,$L10,#REF!)) -> #REF! | Y10: =IF($L10="","",SUMIF(#REF!,$L10,#REF!)) -> #REF! | AA10: =IF($L10="","",SUMIF(#REF!,$L10,#REF!)) -> #REF! | AB10: =IF($L10="","",SUMIF(#REF!,$L10,#REF!)) -> #REF! | AD10: =IF($L10="","",SUMIF(#REF!,$L10,#REF!)) -> #REF! | AE10: =IF($L10="","",SUMIF(#REF!,$L10,#REF!)) -> #REF! | AG10: =IF($L10="","",SUMIF(#REF!,$L10,#REF!)) -> #REF!
A11: Eric Spieguel | B11: Data Engineer | C11: Labs | D11: {=IFERROR(_xlfn.TEXTJOIN(", ",TRUE,_xlfn.UNIQUE(_xlfn._xlws.FILTER(#REF!,(#REF!="Final")*(COUNTIFS('[1]Demand Capacity'!$B:$B,$A11,'[1]Demand Capacity'!$A:$A,#REF!)>0),""))),"")} | E11: Asa Baylus | F11: Contractor | G11: Marvik | I11: DS | J11: Developer | K11: Senior | L11: ericspiguel | M11: =IF($L11="","",SUMIF(#REF!,$L11,#REF!)) -> #REF! | O11: =IF($L11="","",SUMIF(#REF!,$L11,#REF!)) -> #REF! | P11: =IF($L11="","",SUMIF(#REF!,$L11,#REF!)) -> #REF! | R11: =IF($L11="","",SUMIF(#REF!,$L11,#REF!)) -> #REF! | S11: =IF($L11="","",SUMIF(#REF!,$L11,#REF!)) -> #REF! | U11: =IF($L11="","",SUMIF(#REF!,$L11,#REF!)) -> #REF! | V11: =IF($L11="","",SUMIF(#REF!,$L11,#REF!)) -> #REF! | X11: =IF($L11="","",SUMIF(#REF!,$L11,#REF!)) -> #REF! | Y11: =IF($L11="","",SUMIF(#REF!,$L11,#REF!)) -> #REF! | AA11: =IF($L11="","",SUMIF(#REF!,$L11,#REF!)) -> #REF! | AB11: =IF($L11="","",SUMIF(#REF!,$L11,#REF!)) -> #REF! | AD11: =IF($L11="","",SUMIF(#REF!,$L11,#REF!)) -> #REF! | AE11: =IF($L11="","",SUMIF(#REF!,$L11,#REF!)) -> #REF! | AG11: =IF($L11="","",SUMIF(#REF!,$L11,#REF!)) -> #REF!
A12: Juan Oliu | B12: Architect / Lead | C12: Labs | D12: {=IFERROR(_xlfn.TEXTJOIN(", ",TRUE,_xlfn.UNIQUE(_xlfn._xlws.FILTER(#REF!,(#REF!="Final")*(COUNTIFS('[1]Demand Capacity'!$B:$B,$A12,'[1]Demand Capacity'!$A:$A,#REF!)>0),""))),"")} | E12: Asa Baylus | F12: Contractor | G12: Marvik | I12: Full Stack | J12: Developer | K12: Lead | L12: jmoliugp | M12: =IF($L12="","",SUMIF(#REF!,$L12,#REF!)) -> #REF! | O12: =IF($L12="","",SUMIF(#REF!,$L12,#REF!)) -> #REF! | P12: =IF($L12="","",SUMIF(#REF!,$L12,#REF!)) -> #REF! | R12: =IF($L12="","",SUMIF(#REF!,$L12,#REF!)) -> #REF! | S12: =IF($L12="","",SUMIF(#REF!,$L12,#REF!)) -> #REF! | U12: =IF($L12="","",SUMIF(#REF!,$L12,#REF!)) -> #REF! | V12: =IF($L12="","",SUMIF(#REF!,$L12,#REF!)) -> #REF! | X12: =IF($L12="","",SUMIF(#REF!,$L12,#REF!)) -> #REF! | Y12: =IF($L12="","",SUMIF(#REF!,$L12,#REF!)) -> #REF! | AA12: =IF($L12="","",SUMIF(#REF!,$L12,#REF!)) -> #REF! | AB12: =IF($L12="","",SUMIF(#REF!,$L12,#REF!)) -> #REF! | AD12: =IF($L12="","",SUMIF(#REF!,$L12,#REF!)) -> #REF! | AE12: =IF($L12="","",SUMIF(#REF!,$L12,#REF!)) -> #REF! | AG12: =IF($L12="","",SUMIF(#REF!,$L12,#REF!)) -> #REF!
A13: Aaron Entwistle | B13: Senior Platform Engineer | C13: Platform | D13: {=IFERROR(_xlfn.TEXTJOIN(", ",TRUE,_xlfn.UNIQUE(_xlfn._xlws.FILTER(#REF!,(#REF!="Final")*(COUNTIFS('[1]Demand Capacity'!$B:$B,$A13,'[1]Demand Capacity'!$A:$A,#REF!)>0),""))),"")} | E13: Chris Bown | F13: FTE | G13: Stratus | H13: Phoenix | I13: DevOps | J13: Developer | K13: Senior | L13: aaronentwistle | M13: =IF($L13="","",SUMIF(#REF!,$L13,#REF!)) -> #REF! | O13: =IF($L13="","",SUMIF(#REF!,$L13,#REF!)) -> #REF! | P13: =IF($L13="","",SUMIF(#REF!,$L13,#REF!)) -> #REF! | R13: =IF($L13="","",SUMIF(#REF!,$L13,#REF!)) -> #REF! | S13: =IF($L13="","",SUMIF(#REF!,$L13,#REF!)) -> #REF! | U13: =IF($L13="","",SUMIF(#REF!,$L13,#REF!)) -> #REF! | V13: =IF($L13="","",SUMIF(#REF!,$L13,#REF!)) -> #REF! | X13: =IF($L13="","",SUMIF(#REF!,$L13,#REF!)) -> #REF! | Y13: =IF($L13="","",SUMIF(#REF!,$L13,#REF!)) -> #REF! | AA13: =IF($L13="","",SUMIF(#REF!,$L13,#REF!)) -> #REF! | AB13: =IF($L13="","",SUMIF(#REF!,$L13,#REF!)) -> #REF! | AD13: =IF($L13="","",SUMIF(#REF!,$L13,#REF!)) -> #REF! | AE13: =IF($L13="","",SUMIF(#REF!,$L13,#REF!)) -> #REF! | AG13: =IF($L13="","",SUMIF(#REF!,$L13,#REF!)) -> #REF!
A14: Anisah Reed | B14: Platform Engineer | C14: Platform | D14: {=IFERROR(_xlfn.TEXTJOIN(", ",TRUE,_xlfn.UNIQUE(_xlfn._xlws.FILTER(#REF!,(#REF!="Final")*(COUNTIFS('[1]Demand Capacity'!$B:$B,$A14,'[1]Demand Capacity'!$A:$A,#REF!)>0),""))),"")} | E14: Chris Bown | F14: Contractor | G14: Stratus | H14: Houston | I14: DevOps | J14: Developer | K14: Mid | L14: AnisahReed | M14: =IF($L14="","",SUMIF(#REF!,$L14,#REF!)) -> #REF! | O14: =IF($L14="","",SUMIF(#REF!,$L14,#REF!)) -> #REF! | P14: =IF($L14="","",SUMIF(#REF!,$L14,#REF!)) -> #REF! | R14: =IF($L14="","",SUMIF(#REF!,$L14,#REF!)) -> #REF! | S14: =IF($L14="","",SUMIF(#REF!,$L14,#REF!)) -> #REF! | U14: =IF($L14="","",SUMIF(#REF!,$L14,#REF!)) -> #REF! | V14: =IF($L14="","",SUMIF(#REF!,$L14,#REF!)) -> #REF! | X14: =IF($L14="","",SUMIF(#REF!,$L14,#REF!)) -> #REF! | Y14: =IF($L14="","",SUMIF(#REF!,$L14,#REF!)) -> #REF! | AA14: =IF($L14="","",SUMIF(#REF!,$L14,#REF!)) -> #REF! | AB14: =IF($L14="","",SUMIF(#REF!,$L14,#REF!)) -> #REF! | AD14: =IF($L14="","",SUMIF(#REF!,$L14,#REF!)) -> #REF! | AE14: =IF($L14="","",SUMIF(#REF!,$L14,#REF!)) -> #REF! | AG14: =IF($L14="","",SUMIF(#REF!,$L14,#REF!)) -> #REF!
A15: Zach Ward | B15: Platform Engineer | C15: Platform | D15: {=IFERROR(_xlfn.TEXTJOIN(", ",TRUE,_xlfn.UNIQUE(_xlfn._xlws.FILTER(#REF!,(#REF!="Final")*(COUNTIFS('[1]Demand Capacity'!$B:$B,$A15,'[1]Demand Capacity'!$A:$A,#REF!)>0),""))),"")} | E15: Chris Bown | F15: FTE | G15: Stratus | H15: San Diego | I15: DevOps | J15: Developer | K15: Mid | L15: zwardstratus | M15: =IF($L15="","",SUMIF(#REF!,$L15,#REF!)) -> #REF! | O15: =IF($L15="","",SUMIF(#REF!,$L15,#REF!)) -> #REF! | P15: =IF($L15="","",SUMIF(#REF!,$L15,#REF!)) -> #REF! | R15: =IF($L15="","",SUMIF(#REF!,$L15,#REF!)) -> #REF! | S15: =IF($L15="","",SUMIF(#REF!,$L15,#REF!)) -> #REF! | U15: =IF($L15="","",SUMIF(#REF!,$L15,#REF!)) -> #REF! | V15: =IF($L15="","",SUMIF(#REF!,$L15,#REF!)) -> #REF! | X15: =IF($L15="","",SUMIF(#REF!,$L15,#REF!)) -> #REF! | Y15: =IF($L15="","",SUMIF(#REF!,$L15,#REF!)) -> #REF! | AA15: =IF($L15="","",SUMIF(#REF!,$L15,#REF!)) -> #REF! | AB15: =IF($L15="","",SUMIF(#REF!,$L15,#REF!)) -> #REF! | AD15: =IF($L15="","",SUMIF(#REF!,$L15,#REF!)) -> #REF! | AE15: =IF($L15="","",SUMIF(#REF!,$L15,#REF!)) -> #REF! | AG15: =IF($L15="","",SUMIF(#REF!,$L15,#REF!)) -> #REF!
A16: Kyle Snyder | B16: IT (Platform team) | C16: Platform | D16: {=IFERROR(_xlfn.TEXTJOIN(", ",TRUE,_xlfn.UNIQUE(_xlfn._xlws.FILTER(#REF!,(#REF!="Final")*(COUNTIFS('[1]Demand Capacity'!$B:$B,$A16,'[1]Demand Capacity'!$A:$A,#REF!)>0),""))),"")} | E16: Chris Bown | F16: FTE | G16: Stratus | H16: Kansas City | I16: IT | J16: Other | K16: Mid | L16: kylesnydergogtp | M16: =IF($L16="","",SUMIF(#REF!,$L16,#REF!)) -> #REF! | O16: =IF($L16="","",SUMIF(#REF!,$L16,#REF!)) -> #REF! | P16: =IF($L16="","",SUMIF(#REF!,$L16,#REF!)) -> #REF! | R16: =IF($L16="","",SUMIF(#REF!,$L16,#REF!)) -> #REF! | S16: =IF($L16="","",SUMIF(#REF!,$L16,#REF!)) -> #REF! | U16: =IF($L16="","",SUMIF(#REF!,$L16,#REF!)) -> #REF! | V16: =IF($L16="","",SUMIF(#REF!,$L16,#REF!)) -> #REF! | X16: =IF($L16="","",SUMIF(#REF!,$L16,#REF!)) -> #REF! | Y16: =IF($L16="","",SUMIF(#REF!,$L16,#REF!)) -> #REF! | AA16: =IF($L16="","",SUMIF(#REF!,$L16,#REF!)) -> #REF! | AB16: =IF($L16="","",SUMIF(#REF!,$L16,#REF!)) -> #REF! | AD16: =IF($L16="","",SUMIF(#REF!,$L16,#REF!)) -> #REF! | AE16: =IF($L16="","",SUMIF(#REF!,$L16,#REF!)) -> #REF! | AG16: =IF($L16="","",SUMIF(#REF!,$L16,#REF!)) -> #REF!
A17: Antonio Pola | B17: Principal Engineer / Tech Lead | C17: Core | D17: {=IFERROR(_xlfn.TEXTJOIN(", ",TRUE,_xlfn.UNIQUE(_xlfn._xlws.FILTER(#REF!,(#REF!="Final")*(COUNTIFS('[1]Demand Capacity'!$B:$B,$A17,'[1]Demand Capacity'!$A:$A,#REF!)>0),""))),"")} | E17: Anthony Anderson | F17: Contractor (FTE-equivalent) | G17: Rippling | H17: Mexico | I17: Full Stack | J17: Developer | K17: Principal | L17: AntonioPolaGTP | M17: =IF($L17="","",SUMIF(#REF!,$L17,#REF!)) -> #REF! | O17: =IF($L17="","",SUMIF(#REF!,$L17,#REF!)) -> #REF! | P17: =IF($L17="","",SUMIF(#REF!,$L17,#REF!)) -> #REF! | R17: =IF($L17="","",SUMIF(#REF!,$L17,#REF!)) -> #REF! | S17: =IF($L17="","",SUMIF(#REF!,$L17,#REF!)) -> #REF! | U17: =IF($L17="","",SUMIF(#REF!,$L17,#REF!)) -> #REF! | V17: =IF($L17="","",SUMIF(#REF!,$L17,#REF!)) -> #REF! | X17: =IF($L17="","",SUMIF(#REF!,$L17,#REF!)) -> #REF! | Y17: =IF($L17="","",SUMIF(#REF!,$L17,#REF!)) -> #REF! | AA17: =IF($L17="","",SUMIF(#REF!,$L17,#REF!)) -> #REF! | AB17: =IF($L17="","",SUMIF(#REF!,$L17,#REF!)) -> #REF! | AD17: =IF($L17="","",SUMIF(#REF!,$L17,#REF!)) -> #REF! | AE17: =IF($L17="","",SUMIF(#REF!,$L17,#REF!)) -> #REF! | AG17: =IF($L17="","",SUMIF(#REF!,$L17,#REF!)) -> #REF!
A18: Adrian Castillo | B18: Full Stack Engineer (Lead-track) | C18: Core | D18: {=IFERROR(_xlfn.TEXTJOIN(", ",TRUE,_xlfn.UNIQUE(_xlfn._xlws.FILTER(#REF!,(#REF!="Final")*(COUNTIFS('[1]Demand Capacity'!$B:$B,$A18,'[1]Demand Capacity'!$A:$A,#REF!)>0),""))),"")} | E18: Anthony Anderson | F18: Contractor (FTE-equivalent) | G18: Stratus | H18: Mexico | I18: Full Stack | J18: Developer | K18: Senior | L18: adrianCastillo-gtp | M18: =IF($L18="","",SUMIF(#REF!,$L18,#REF!)) -> #REF! | O18: =IF($L18="","",SUMIF(#REF!,$L18,#REF!)) -> #REF! | P18: =IF($L18="","",SUMIF(#REF!,$L18,#REF!)) -> #REF! | R18: =IF($L18="","",SUMIF(#REF!,$L18,#REF!)) -> #REF! | S18: =IF($L18="","",SUMIF(#REF!,$L18,#REF!)) -> #REF! | U18: =IF($L18="","",SUMIF(#REF!,$L18,#REF!)) -> #REF! | V18: =IF($L18="","",SUMIF(#REF!,$L18,#REF!)) -> #REF! | X18: =IF($L18="","",SUMIF(#REF!,$L18,#REF!)) -> #REF! | Y18: =IF($L18="","",SUMIF(#REF!,$L18,#REF!)) -> #REF! | AA18: =IF($L18="","",SUMIF(#REF!,$L18,#REF!)) -> #REF! | AB18: =IF($L18="","",SUMIF(#REF!,$L18,#REF!)) -> #REF! | AD18: =IF($L18="","",SUMIF(#REF!,$L18,#REF!)) -> #REF! | AE18: =IF($L18="","",SUMIF(#REF!,$L18,#REF!)) -> #REF! | AG18: =IF($L18="","",SUMIF(#REF!,$L18,#REF!)) -> #REF!
A19: Matt Duffy | B19: Full Stack Engineer | C19: Core | D19: {=IFERROR(_xlfn.TEXTJOIN(", ",TRUE,_xlfn.UNIQUE(_xlfn._xlws.FILTER(#REF!,(#REF!="Final")*(COUNTIFS('[1]Demand Capacity'!$B:$B,$A19,'[1]Demand Capacity'!$A:$A,#REF!)>0),""))),"")} | E19: Anthony Anderson | F19: FTE | G19: Stratus | H19: Wisconsin | I19: Full Stack | J19: Developer | K19: Senior | L19: mduffy-gtp | M19: =IF($L19="","",SUMIF(#REF!,$L19,#REF!)) -> #REF! | O19: =IF($L19="","",SUMIF(#REF!,$L19,#REF!)) -> #REF! | P19: =IF($L19="","",SUMIF(#REF!,$L19,#REF!)) -> #REF! | R19: =IF($L19="","",SUMIF(#REF!,$L19,#REF!)) -> #REF! | S19: =IF($L19="","",SUMIF(#REF!,$L19,#REF!)) -> #REF! | U19: =IF($L19="","",SUMIF(#REF!,$L19,#REF!)) -> #REF! | V19: =IF($L19="","",SUMIF(#REF!,$L19,#REF!)) -> #REF! | X19: =IF($L19="","",SUMIF(#REF!,$L19,#REF!)) -> #REF! | Y19: =IF($L19="","",SUMIF(#REF!,$L19,#REF!)) -> #REF! | AA19: =IF($L19="","",SUMIF(#REF!,$L19,#REF!)) -> #REF! | AB19: =IF($L19="","",SUMIF(#REF!,$L19,#REF!)) -> #REF! | AD19: =IF($L19="","",SUMIF(#REF!,$L19,#REF!)) -> #REF! | AE19: =IF($L19="","",SUMIF(#REF!,$L19,#REF!)) -> #REF! | AG19: =IF($L19="","",SUMIF(#REF!,$L19,#REF!)) -> #REF!
A20: Hector Tinajero | B20: Senior Full Stack / Tech Lead | C20: Core | D20: {=IFERROR(_xlfn.TEXTJOIN(", ",TRUE,_xlfn.UNIQUE(_xlfn._xlws.FILTER(#REF!,(#REF!="Final")*(COUNTIFS('[1]Demand Capacity'!$B:$B,$A20,'[1]Demand Capacity'!$A:$A,#REF!)>0),""))),"")} | E20: Asa Baylus | F20: Contractor (FTE-equivalent) | G20: Rippling | H20: Mexico | I20: Full Stack | J20: Developer | K20: Senior | L20: hectortinajerogtp | M20: =IF($L20="","",SUMIF(#REF!,$L20,#REF!)) -> #REF! | O20: =IF($L20="","",SUMIF(#REF!,$L20,#REF!)) -> #REF! | P20: =IF($L20="","",SUMIF(#REF!,$L20,#REF!)) -> #REF! | R20: =IF($L20="","",SUMIF(#REF!,$L20,#REF!)) -> #REF! | S20: =IF($L20="","",SUMIF(#REF!,$L20,#REF!)) -> #REF! | U20: =IF($L20="","",SUMIF(#REF!,$L20,#REF!)) -> #REF! | V20: =IF($L20="","",SUMIF(#REF!,$L20,#REF!)) -> #REF! | X20: =IF($L20="","",SUMIF(#REF!,$L20,#REF!)) -> #REF! | Y20: =IF($L20="","",SUMIF(#REF!,$L20,#REF!)) -> #REF! | AA20: =IF($L20="","",SUMIF(#REF!,$L20,#REF!)) -> #REF! | AB20: =IF($L20="","",SUMIF(#REF!,$L20,#REF!)) -> #REF! | AD20: =IF($L20="","",SUMIF(#REF!,$L20,#REF!)) -> #REF! | AE20: =IF($L20="","",SUMIF(#REF!,$L20,#REF!)) -> #REF! | AG20: =IF($L20="","",SUMIF(#REF!,$L20,#REF!)) -> #REF!
A21: Maaz Qureshi | B21: Senior Full Stack Engineer | C21: Core | D21: {=IFERROR(_xlfn.TEXTJOIN(", ",TRUE,_xlfn.UNIQUE(_xlfn._xlws.FILTER(#REF!,(#REF!="Final")*(COUNTIFS('[1]Demand Capacity'!$B:$B,$A21,'[1]Demand Capacity'!$A:$A,#REF!)>0),""))),"")} | E21: Asa Baylus | F21: FTE | G21: Stratus | I21: Full Stack | J21: Developer | K21: Senior | L21: maazq1 | M21: =IF($L21="","",SUMIF(#REF!,$L21,#REF!)) -> #REF! | O21: =IF($L21="","",SUMIF(#REF!,$L21,#REF!)) -> #REF! | P21: =IF($L21="","",SUMIF(#REF!,$L21,#REF!)) -> #REF! | R21: =IF($L21="","",SUMIF(#REF!,$L21,#REF!)) -> #REF! | S21: =IF($L21="","",SUMIF(#REF!,$L21,#REF!)) -> #REF! | U21: =IF($L21="","",SUMIF(#REF!,$L21,#REF!)) -> #REF! | V21: =IF($L21="","",SUMIF(#REF!,$L21,#REF!)) -> #REF! | X21: =IF($L21="","",SUMIF(#REF!,$L21,#REF!)) -> #REF! | Y21: =IF($L21="","",SUMIF(#REF!,$L21,#REF!)) -> #REF! | AA21: =IF($L21="","",SUMIF(#REF!,$L21,#REF!)) -> #REF! | AB21: =IF($L21="","",SUMIF(#REF!,$L21,#REF!)) -> #REF! | AD21: =IF($L21="","",SUMIF(#REF!,$L21,#REF!)) -> #REF! | AE21: =IF($L21="","",SUMIF(#REF!,$L21,#REF!)) -> #REF! | AG21: =IF($L21="","",SUMIF(#REF!,$L21,#REF!)) -> #REF!
A22: David Rozen | B22: Principal Engineer (Backend) | C22: Core | D22: {=IFERROR(_xlfn.TEXTJOIN(", ",TRUE,_xlfn.UNIQUE(_xlfn._xlws.FILTER(#REF!,(#REF!="Final")*(COUNTIFS('[1]Demand Capacity'!$B:$B,$A22,'[1]Demand Capacity'!$A:$A,#REF!)>0),""))),"")} | E22: Anthony Anderson | F22: Contractor | G22: Marvik | H22: Argentina | I22: Full Stack | J22: Developer | K22: Principal | L22: dvdrozen-stratus | M22: =IF($L22="","",SUMIF(#REF!,$L22,#REF!)) -> #REF! | O22: =IF($L22="","",SUMIF(#REF!,$L22,#REF!)) -> #REF! | P22: =IF($L22="","",SUMIF(#REF!,$L22,#REF!)) -> #REF! | R22: =IF($L22="","",SUMIF(#REF!,$L22,#REF!)) -> #REF! | S22: =IF($L22="","",SUMIF(#REF!,$L22,#REF!)) -> #REF! | U22: =IF($L22="","",SUMIF(#REF!,$L22,#REF!)) -> #REF! | V22: =IF($L22="","",SUMIF(#REF!,$L22,#REF!)) -> #REF! | X22: =IF($L22="","",SUMIF(#REF!,$L22,#REF!)) -> #REF! | Y22: =IF($L22="","",SUMIF(#REF!,$L22,#REF!)) -> #REF! | AA22: =IF($L22="","",SUMIF(#REF!,$L22,#REF!)) -> #REF! | AB22: =IF($L22="","",SUMIF(#REF!,$L22,#REF!)) -> #REF! | AD22: =IF($L22="","",SUMIF(#REF!,$L22,#REF!)) -> #REF! | AE22: =IF($L22="","",SUMIF(#REF!,$L22,#REF!)) -> #REF! | AG22: =IF($L22="","",SUMIF(#REF!,$L22,#REF!)) -> #REF!
A23: Ryan Trimble | B23: Senior Front-end Engineer | C23: Core | D23: {=IFERROR(_xlfn.TEXTJOIN(", ",TRUE,_xlfn.UNIQUE(_xlfn._xlws.FILTER(#REF!,(#REF!="Final")*(COUNTIFS('[1]Demand Capacity'!$B:$B,$A23,'[1]Demand Capacity'!$A:$A,#REF!)>0),""))),"")} | E23: Anthony Anderson | F23: FTE | G23: Stratus | I23: Full Stack | J23: Developer | K23: Senior | L23: ryantrimble-stratus | M23: =IF($L23="","",SUMIF(#REF!,$L23,#REF!)) -> #REF! | O23: =IF($L23="","",SUMIF(#REF!,$L23,#REF!)) -> #REF! | P23: =IF($L23="","",SUMIF(#REF!,$L23,#REF!)) -> #REF! | R23: =IF($L23="","",SUMIF(#REF!,$L23,#REF!)) -> #REF! | S23: =IF($L23="","",SUMIF(#REF!,$L23,#REF!)) -> #REF! | U23: =IF($L23="","",SUMIF(#REF!,$L23,#REF!)) -> #REF! | V23: =IF($L23="","",SUMIF(#REF!,$L23,#REF!)) -> #REF! | X23: =IF($L23="","",SUMIF(#REF!,$L23,#REF!)) -> #REF! | Y23: =IF($L23="","",SUMIF(#REF!,$L23,#REF!)) -> #REF! | AA23: =IF($L23="","",SUMIF(#REF!,$L23,#REF!)) -> #REF! | AB23: =IF($L23="","",SUMIF(#REF!,$L23,#REF!)) -> #REF! | AD23: =IF($L23="","",SUMIF(#REF!,$L23,#REF!)) -> #REF! | AE23: =IF($L23="","",SUMIF(#REF!,$L23,#REF!)) -> #REF! | AG23: =IF($L23="","",SUMIF(#REF!,$L23,#REF!)) -> #REF!
A24: Ahmed Sohail | B24: Full Stack Engineer | C24: Core | D24: {=IFERROR(_xlfn.TEXTJOIN(", ",TRUE,_xlfn.UNIQUE(_xlfn._xlws.FILTER(#REF!,(#REF!="Final")*(COUNTIFS('[1]Demand Capacity'!$B:$B,$A24,'[1]Demand Capacity'!$A:$A,#REF!)>0),""))),"")} | E24: Asa Baylus | F24: FTE | G24: Stratus | I24: Full Stack | J24: Developer | K24: Senior | L24: aahmedstratus | M24: =IF($L24="","",SUMIF(#REF!,$L24,#REF!)) -> #REF! | O24: =IF($L24="","",SUMIF(#REF!,$L24,#REF!)) -> #REF! | P24: =IF($L24="","",SUMIF(#REF!,$L24,#REF!)) -> #REF! | R24: =IF($L24="","",SUMIF(#REF!,$L24,#REF!)) -> #REF! | S24: =IF($L24="","",SUMIF(#REF!,$L24,#REF!)) -> #REF! | U24: =IF($L24="","",SUMIF(#REF!,$L24,#REF!)) -> #REF! | V24: =IF($L24="","",SUMIF(#REF!,$L24,#REF!)) -> #REF! | X24: =IF($L24="","",SUMIF(#REF!,$L24,#REF!)) -> #REF! | Y24: =IF($L24="","",SUMIF(#REF!,$L24,#REF!)) -> #REF! | AA24: =IF($L24="","",SUMIF(#REF!,$L24,#REF!)) -> #REF! | AB24: =IF($L24="","",SUMIF(#REF!,$L24,#REF!)) -> #REF! | AD24: =IF($L24="","",SUMIF(#REF!,$L24,#REF!)) -> #REF! | AE24: =IF($L24="","",SUMIF(#REF!,$L24,#REF!)) -> #REF! | AG24: =IF($L24="","",SUMIF(#REF!,$L24,#REF!)) -> #REF!
A25: Joe Hosman | B25: Full Stack Engineer | C25: Core | D25: {=IFERROR(_xlfn.TEXTJOIN(", ",TRUE,_xlfn.UNIQUE(_xlfn._xlws.FILTER(#REF!,(#REF!="Final")*(COUNTIFS('[1]Demand Capacity'!$B:$B,$A25,'[1]Demand Capacity'!$A:$A,#REF!)>0),""))),"")} | E25: Asa Baylus | F25: FTE | G25: Stratus | H25: Kansas City | I25: Desktop | J25: Developer | K25: Senior | L25: JoeGoGTP | M25: =IF($L25="","",SUMIF(#REF!,$L25,#REF!)) -> #REF! | O25: =IF($L25="","",SUMIF(#REF!,$L25,#REF!)) -> #REF! | P25: =IF($L25="","",SUMIF(#REF!,$L25,#REF!)) -> #REF! | R25: =IF($L25="","",SUMIF(#REF!,$L25,#REF!)) -> #REF! | S25: =IF($L25="","",SUMIF(#REF!,$L25,#REF!)) -> #REF! | U25: =IF($L25="","",SUMIF(#REF!,$L25,#REF!)) -> #REF! | V25: =IF($L25="","",SUMIF(#REF!,$L25,#REF!)) -> #REF! | X25: =IF($L25="","",SUMIF(#REF!,$L25,#REF!)) -> #REF! | Y25: =IF($L25="","",SUMIF(#REF!,$L25,#REF!)) -> #REF! | AA25: =IF($L25="","",SUMIF(#REF!,$L25,#REF!)) -> #REF! | AB25: =IF($L25="","",SUMIF(#REF!,$L25,#REF!)) -> #REF! | AD25: =IF($L25="","",SUMIF(#REF!,$L25,#REF!)) -> #REF! | AE25: =IF($L25="","",SUMIF(#REF!,$L25,#REF!)) -> #REF! | AG25: =IF($L25="","",SUMIF(#REF!,$L25,#REF!)) -> #REF!
A26: Ignacio Harretche | B26: Full Stack Engineer | C26: Core | D26: {=IFERROR(_xlfn.TEXTJOIN(", ",TRUE,_xlfn.UNIQUE(_xlfn._xlws.FILTER(#REF!,(#REF!="Final")*(COUNTIFS('[1]Demand Capacity'!$B:$B,$A26,'[1]Demand Capacity'!$A:$A,#REF!)>0),""))),"")} | E26: Asa Baylus | F26: Contractor | G26: Marvik | I26: Desktop | J26: Developer | K26: Senior | L26: ignacio-harretche-stratus | M26: =IF($L26="","",SUMIF(#REF!,$L26,#REF!)) -> #REF! | O26: =IF($L26="","",SUMIF(#REF!,$L26,#REF!)) -> #REF! | P26: =IF($L26="","",SUMIF(#REF!,$L26,#REF!)) -> #REF! | R26: =IF($L26="","",SUMIF(#REF!,$L26,#REF!)) -> #REF! | S26: =IF($L26="","",SUMIF(#REF!,$L26,#REF!)) -> #REF! | U26: =IF($L26="","",SUMIF(#REF!,$L26,#REF!)) -> #REF! | V26: =IF($L26="","",SUMIF(#REF!,$L26,#REF!)) -> #REF! | X26: =IF($L26="","",SUMIF(#REF!,$L26,#REF!)) -> #REF! | Y26: =IF($L26="","",SUMIF(#REF!,$L26,#REF!)) -> #REF! | AA26: =IF($L26="","",SUMIF(#REF!,$L26,#REF!)) -> #REF! | AB26: =IF($L26="","",SUMIF(#REF!,$L26,#REF!)) -> #REF! | AD26: =IF($L26="","",SUMIF(#REF!,$L26,#REF!)) -> #REF! | AE26: =IF($L26="","",SUMIF(#REF!,$L26,#REF!)) -> #REF! | AG26: =IF($L26="","",SUMIF(#REF!,$L26,#REF!)) -> #REF!
A27: Steve Rives | B27: Lead Engineer — Workstation/Print | C27: Core | D27: {=IFERROR(_xlfn.TEXTJOIN(", ",TRUE,_xlfn.UNIQUE(_xlfn._xlws.FILTER(#REF!,(#REF!="Final")*(COUNTIFS('[1]Demand Capacity'!$B:$B,$A27,'[1]Demand Capacity'!$A:$A,#REF!)>0),""))),"")} | E27: Anthony Anderson | F27: FTE | G27: Stratus | H27: Kansas City | I27: Full Stack | J27: Developer | K27: Lead | L27: srives-gtp | M27: =IF($L27="","",SUMIF(#REF!,$L27,#REF!)) -> #REF! | O27: =IF($L27="","",SUMIF(#REF!,$L27,#REF!)) -> #REF! | P27: =IF($L27="","",SUMIF(#REF!,$L27,#REF!)) -> #REF! | R27: =IF($L27="","",SUMIF(#REF!,$L27,#REF!)) -> #REF! | S27: =IF($L27="","",SUMIF(#REF!,$L27,#REF!)) -> #REF! | U27: =IF($L27="","",SUMIF(#REF!,$L27,#REF!)) -> #REF! | V27: =IF($L27="","",SUMIF(#REF!,$L27,#REF!)) -> #REF! | X27: =IF($L27="","",SUMIF(#REF!,$L27,#REF!)) -> #REF! | Y27: =IF($L27="","",SUMIF(#REF!,$L27,#REF!)) -> #REF! | AA27: =IF($L27="","",SUMIF(#REF!,$L27,#REF!)) -> #REF! | AB27: =IF($L27="","",SUMIF(#REF!,$L27,#REF!)) -> #REF! | AD27: =IF($L27="","",SUMIF(#REF!,$L27,#REF!)) -> #REF! | AE27: =IF($L27="","",SUMIF(#REF!,$L27,#REF!)) -> #REF! | AG27: =IF($L27="","",SUMIF(#REF!,$L27,#REF!)) -> #REF!
A28: Fernando Bastos | B28: Desktop Engineer | C28: Core | D28: {=IFERROR(_xlfn.TEXTJOIN(", ",TRUE,_xlfn.UNIQUE(_xlfn._xlws.FILTER(#REF!,(#REF!="Final")*(COUNTIFS('[1]Demand Capacity'!$B:$B,$A28,'[1]Demand Capacity'!$A:$A,#REF!)>0),""))),"")} | E28: Anthony Anderson | F28: Contractor (FTE-equivalent) | G28: Rippling | H28: Brazil | I28: Desktop | J28: Developer | K28: Senior | L28: fernandobastosgogtp | M28: =IF($L28="","",SUMIF(#REF!,$L28,#REF!)) -> #REF! | O28: =IF($L28="","",SUMIF(#REF!,$L28,#REF!)) -> #REF! | P28: =IF($L28="","",SUMIF(#REF!,$L28,#REF!)) -> #REF! | R28: =IF($L28="","",SUMIF(#REF!,$L28,#REF!)) -> #REF! | S28: =IF($L28="","",SUMIF(#REF!,$L28,#REF!)) -> #REF! | U28: =IF($L28="","",SUMIF(#REF!,$L28,#REF!)) -> #REF! | V28: =IF($L28="","",SUMIF(#REF!,$L28,#REF!)) -> #REF! | X28: =IF($L28="","",SUMIF(#REF!,$L28,#REF!)) -> #REF! | Y28: =IF($L28="","",SUMIF(#REF!,$L28,#REF!)) -> #REF! | AA28: =IF($L28="","",SUMIF(#REF!,$L28,#REF!)) -> #REF! | AB28: =IF($L28="","",SUMIF(#REF!,$L28,#REF!)) -> #REF! | AD28: =IF($L28="","",SUMIF(#REF!,$L28,#REF!)) -> #REF! | AE28: =IF($L28="","",SUMIF(#REF!,$L28,#REF!)) -> #REF! | AG28: =IF($L28="","",SUMIF(#REF!,$L28,#REF!)) -> #REF!
A29: Anthony Lehenbauer | B29: Lead — Field Orders | C29: Core | D29: {=IFERROR(_xlfn.TEXTJOIN(", ",TRUE,_xlfn.UNIQUE(_xlfn._xlws.FILTER(#REF!,(#REF!="Final")*(COUNTIFS('[1]Demand Capacity'!$B:$B,$A29,'[1]Demand Capacity'!$A:$A,#REF!)>0),""))),"")} | E29: Anthony Anderson | F29: FTE | G29: Stratus | H29: Ashburn, Virginia Gainesville, FL | I29: Full Stack | J29: Developer | K29: Senior | L29: gtp-anthony-lehenbauer | M29: =IF($L29="","",SUMIF(#REF!,$L29,#REF!)) -> #REF! | O29: =IF($L29="","",SUMIF(#REF!,$L29,#REF!)) -> #REF! | P29: =IF($L29="","",SUMIF(#REF!,$L29,#REF!)) -> #REF! | R29: =IF($L29="","",SUMIF(#REF!,$L29,#REF!)) -> #REF! | S29: =IF($L29="","",SUMIF(#REF!,$L29,#REF!)) -> #REF! | U29: =IF($L29="","",SUMIF(#REF!,$L29,#REF!)) -> #REF! | V29: =IF($L29="","",SUMIF(#REF!,$L29,#REF!)) -> #REF! | X29: =IF($L29="","",SUMIF(#REF!,$L29,#REF!)) -> #REF! | Y29: =IF($L29="","",SUMIF(#REF!,$L29,#REF!)) -> #REF! | AA29: =IF($L29="","",SUMIF(#REF!,$L29,#REF!)) -> #REF! | AB29: =IF($L29="","",SUMIF(#REF!,$L29,#REF!)) -> #REF! | AD29: =IF($L29="","",SUMIF(#REF!,$L29,#REF!)) -> #REF! | AE29: =IF($L29="","",SUMIF(#REF!,$L29,#REF!)) -> #REF! | AG29: =IF($L29="","",SUMIF(#REF!,$L29,#REF!)) -> #REF!
A30: Lautaro Araujo | B30: Cloud / Platform Engineer | C30: Core | D30: {=IFERROR(_xlfn.TEXTJOIN(", ",TRUE,_xlfn.UNIQUE(_xlfn._xlws.FILTER(#REF!,(#REF!="Final")*(COUNTIFS('[1]Demand Capacity'!$B:$B,$A30,'[1]Demand Capacity'!$A:$A,#REF!)>0),""))),"")} | E30: Anthony Anderson | F30: Contractor (FTE-equivalent) | G30: Rippling | H30: Argentina | I30: Backend | J30: Developer | K30: Mid | L30: laaraujo | M30: =IF($L30="","",SUMIF(#REF!,$L30,#REF!)) -> #REF! | O30: =IF($L30="","",SUMIF(#REF!,$L30,#REF!)) -> #REF! | P30: =IF($L30="","",SUMIF(#REF!,$L30,#REF!)) -> #REF! | R30: =IF($L30="","",SUMIF(#REF!,$L30,#REF!)) -> #REF! | S30: =IF($L30="","",SUMIF(#REF!,$L30,#REF!)) -> #REF! | U30: =IF($L30="","",SUMIF(#REF!,$L30,#REF!)) -> #REF! | V30: =IF($L30="","",SUMIF(#REF!,$L30,#REF!)) -> #REF! | X30: =IF($L30="","",SUMIF(#REF!,$L30,#REF!)) -> #REF! | Y30: =IF($L30="","",SUMIF(#REF!,$L30,#REF!)) -> #REF! | AA30: =IF($L30="","",SUMIF(#REF!,$L30,#REF!)) -> #REF! | AB30: =IF($L30="","",SUMIF(#REF!,$L30,#REF!)) -> #REF! | AD30: =IF($L30="","",SUMIF(#REF!,$L30,#REF!)) -> #REF! | AE30: =IF($L30="","",SUMIF(#REF!,$L30,#REF!)) -> #REF! | AG30: =IF($L30="","",SUMIF(#REF!,$L30,#REF!)) -> #REF!
A31: Martin Ferreira | B31: Unity Developer | C31: Core | D31: {=IFERROR(_xlfn.TEXTJOIN(", ",TRUE,_xlfn.UNIQUE(_xlfn._xlws.FILTER(#REF!,(#REF!="Final")*(COUNTIFS('[1]Demand Capacity'!$B:$B,$A31,'[1]Demand Capacity'!$A:$A,#REF!)>0),""))),"")} | E31: Anthony Anderson | F31: Contractor (FTE-equivalent) | G31: Rippling | I31: Backend | J31: Developer | K31: Mid | L31: Martin-Stratus | M31: =IF($L31="","",SUMIF(#REF!,$L31,#REF!)) -> #REF! | O31: =IF($L31="","",SUMIF(#REF!,$L31,#REF!)) -> #REF! | P31: =IF($L31="","",SUMIF(#REF!,$L31,#REF!)) -> #REF! | R31: =IF($L31="","",SUMIF(#REF!,$L31,#REF!)) -> #REF! | S31: =IF($L31="","",SUMIF(#REF!,$L31,#REF!)) -> #REF! | U31: =IF($L31="","",SUMIF(#REF!,$L31,#REF!)) -> #REF! | V31: =IF($L31="","",SUMIF(#REF!,$L31,#REF!)) -> #REF! | X31: =IF($L31="","",SUMIF(#REF!,$L31,#REF!)) -> #REF! | Y31: =IF($L31="","",SUMIF(#REF!,$L31,#REF!)) -> #REF! | AA31: =IF($L31="","",SUMIF(#REF!,$L31,#REF!)) -> #REF! | AB31: =IF($L31="","",SUMIF(#REF!,$L31,#REF!)) -> #REF! | AD31: =IF($L31="","",SUMIF(#REF!,$L31,#REF!)) -> #REF! | AE31: =IF($L31="","",SUMIF(#REF!,$L31,#REF!)) -> #REF! | AG31: =IF($L31="","",SUMIF(#REF!,$L31,#REF!)) -> #REF!
A32: Tomas Gorkin | B32: Engineer — Mobile Viewer | C32: Core | D32: {=IFERROR(_xlfn.TEXTJOIN(", ",TRUE,_xlfn.UNIQUE(_xlfn._xlws.FILTER(#REF!,(#REF!="Final")*(COUNTIFS('[1]Demand Capacity'!$B:$B,$A32,'[1]Demand Capacity'!$A:$A,#REF!)>0),""))),"")} | E32: Anthony Anderson | F32: Contractor (FTE-equivalent) | G32: Rippling | I32: QA | J32: Other | K32: Senior | L32: tomas-stratus | M32: =IF($L32="","",SUMIF(#REF!,$L32,#REF!)) -> #REF! | O32: =IF($L32="","",SUMIF(#REF!,$L32,#REF!)) -> #REF! | P32: =IF($L32="","",SUMIF(#REF!,$L32,#REF!)) -> #REF! | R32: =IF($L32="","",SUMIF(#REF!,$L32,#REF!)) -> #REF! | S32: =IF($L32="","",SUMIF(#REF!,$L32,#REF!)) -> #REF! | U32: =IF($L32="","",SUMIF(#REF!,$L32,#REF!)) -> #REF! | V32: =IF($L32="","",SUMIF(#REF!,$L32,#REF!)) -> #REF! | X32: =IF($L32="","",SUMIF(#REF!,$L32,#REF!)) -> #REF! | Y32: =IF($L32="","",SUMIF(#REF!,$L32,#REF!)) -> #REF! | AA32: =IF($L32="","",SUMIF(#REF!,$L32,#REF!)) -> #REF! | AB32: =IF($L32="","",SUMIF(#REF!,$L32,#REF!)) -> #REF! | AD32: =IF($L32="","",SUMIF(#REF!,$L32,#REF!)) -> #REF! | AE32: =IF($L32="","",SUMIF(#REF!,$L32,#REF!)) -> #REF! | AG32: =IF($L32="","",SUMIF(#REF!,$L32,#REF!)) -> #REF!
A33: Bruce Vaughn | B33: Principal QA Engineer | C33: Core | D33: {=IFERROR(_xlfn.TEXTJOIN(", ",TRUE,_xlfn.UNIQUE(_xlfn._xlws.FILTER(#REF!,(#REF!="Final")*(COUNTIFS('[1]Demand Capacity'!$B:$B,$A33,'[1]Demand Capacity'!$A:$A,#REF!)>0),""))),"")} | E33: Anthony Anderson | F33: FTE | G33: Stratus | H33: Kansas City | I33: QA | J33: Other | K33: Lead | L33: QABruceVaughn | M33: =IF($L33="","",SUMIF(#REF!,$L33,#REF!)) -> #REF! | O33: =IF($L33="","",SUMIF(#REF!,$L33,#REF!)) -> #REF! | P33: =IF($L33="","",SUMIF(#REF!,$L33,#REF!)) -> #REF! | R33: =IF($L33="","",SUMIF(#REF!,$L33,#REF!)) -> #REF! | S33: =IF($L33="","",SUMIF(#REF!,$L33,#REF!)) -> #REF! | U33: =IF($L33="","",SUMIF(#REF!,$L33,#REF!)) -> #REF! | V33: =IF($L33="","",SUMIF(#REF!,$L33,#REF!)) -> #REF! | X33: =IF($L33="","",SUMIF(#REF!,$L33,#REF!)) -> #REF! | Y33: =IF($L33="","",SUMIF(#REF!,$L33,#REF!)) -> #REF! | AA33: =IF($L33="","",SUMIF(#REF!,$L33,#REF!)) -> #REF! | AB33: =IF($L33="","",SUMIF(#REF!,$L33,#REF!)) -> #REF! | AD33: =IF($L33="","",SUMIF(#REF!,$L33,#REF!)) -> #REF! | AE33: =IF($L33="","",SUMIF(#REF!,$L33,#REF!)) -> #REF! | AG33: =IF($L33="","",SUMIF(#REF!,$L33,#REF!)) -> #REF!
A34: Murat Ozel | B34: SDET | C34: Core | D34: {=IFERROR(_xlfn.TEXTJOIN(", ",TRUE,_xlfn.UNIQUE(_xlfn._xlws.FILTER(#REF!,(#REF!="Final")*(COUNTIFS('[1]Demand Capacity'!$B:$B,$A34,'[1]Demand Capacity'!$A:$A,#REF!)>0),""))),"")} | E34: Anthony Anderson | F34: FTE | G34: Stratus | H34: Nashville | I34: QA | J34: Other | K34: Mid | L34: Murat-QA | M34: =IF($L34="","",SUMIF(#REF!,$L34,#REF!)) -> #REF! | O34: =IF($L34="","",SUMIF(#REF!,$L34,#REF!)) -> #REF! | P34: =IF($L34="","",SUMIF(#REF!,$L34,#REF!)) -> #REF! | R34: =IF($L34="","",SUMIF(#REF!,$L34,#REF!)) -> #REF! | S34: =IF($L34="","",SUMIF(#REF!,$L34,#REF!)) -> #REF! | U34: =IF($L34="","",SUMIF(#REF!,$L34,#REF!)) -> #REF! | V34: =IF($L34="","",SUMIF(#REF!,$L34,#REF!)) -> #REF! | X34: =IF($L34="","",SUMIF(#REF!,$L34,#REF!)) -> #REF! | Y34: =IF($L34="","",SUMIF(#REF!,$L34,#REF!)) -> #REF! | AA34: =IF($L34="","",SUMIF(#REF!,$L34,#REF!)) -> #REF! | AB34: =IF($L34="","",SUMIF(#REF!,$L34,#REF!)) -> #REF! | AD34: =IF($L34="","",SUMIF(#REF!,$L34,#REF!)) -> #REF! | AE34: =IF($L34="","",SUMIF(#REF!,$L34,#REF!)) -> #REF! | AG34: =IF($L34="","",SUMIF(#REF!,$L34,#REF!)) -> #REF!
A35: Glenn Holmes | B35: QA Engineer | C35: Core | D35: {=IFERROR(_xlfn.TEXTJOIN(", ",TRUE,_xlfn.UNIQUE(_xlfn._xlws.FILTER(#REF!,(#REF!="Final")*(COUNTIFS('[1]Demand Capacity'!$B:$B,$A35,'[1]Demand Capacity'!$A:$A,#REF!)>0),""))),"")} | E35: Anthony Anderson | F35: FTE | G35: Stratus | H35: Kansas City | I35: QA | J35: Other | K35: Mid | L35: Glenn-QA | M35: =IF($L35="","",SUMIF(#REF!,$L35,#REF!)) -> #REF! | O35: =IF($L35="","",SUMIF(#REF!,$L35,#REF!)) -> #REF! | P35: =IF($L35="","",SUMIF(#REF!,$L35,#REF!)) -> #REF! | R35: =IF($L35="","",SUMIF(#REF!,$L35,#REF!)) -> #REF! | S35: =IF($L35="","",SUMIF(#REF!,$L35,#REF!)) -> #REF! | U35: =IF($L35="","",SUMIF(#REF!,$L35,#REF!)) -> #REF! | V35: =IF($L35="","",SUMIF(#REF!,$L35,#REF!)) -> #REF! | X35: =IF($L35="","",SUMIF(#REF!,$L35,#REF!)) -> #REF! | Y35: =IF($L35="","",SUMIF(#REF!,$L35,#REF!)) -> #REF! | AA35: =IF($L35="","",SUMIF(#REF!,$L35,#REF!)) -> #REF! | AB35: =IF($L35="","",SUMIF(#REF!,$L35,#REF!)) -> #REF! | AD35: =IF($L35="","",SUMIF(#REF!,$L35,#REF!)) -> #REF! | AE35: =IF($L35="","",SUMIF(#REF!,$L35,#REF!)) -> #REF! | AG35: =IF($L35="","",SUMIF(#REF!,$L35,#REF!)) -> #REF!
A36: Chris Cavazos | B36: Publish Support Engineer | C36: Core | D36: {=IFERROR(_xlfn.TEXTJOIN(", ",TRUE,_xlfn.UNIQUE(_xlfn._xlws.FILTER(#REF!,(#REF!="Final")*(COUNTIFS('[1]Demand Capacity'!$B:$B,$A36,'[1]Demand Capacity'!$A:$A,#REF!)>0),""))),"")} | E36: Asa Baylus | F36: FTE | G36: Stratus | H36: Seattle | I36: Full Stack | J36: Developer | K36: Mid | L36: crcavazos | M36: =IF($L36="","",SUMIF(#REF!,$L36,#REF!)) -> #REF! | O36: =IF($L36="","",SUMIF(#REF!,$L36,#REF!)) -> #REF! | P36: =IF($L36="","",SUMIF(#REF!,$L36,#REF!)) -> #REF! | R36: =IF($L36="","",SUMIF(#REF!,$L36,#REF!)) -> #REF! | S36: =IF($L36="","",SUMIF(#REF!,$L36,#REF!)) -> #REF! | U36: =IF($L36="","",SUMIF(#REF!,$L36,#REF!)) -> #REF! | V36: =IF($L36="","",SUMIF(#REF!,$L36,#REF!)) -> #REF! | X36: =IF($L36="","",SUMIF(#REF!,$L36,#REF!)) -> #REF! | Y36: =IF($L36="","",SUMIF(#REF!,$L36,#REF!)) -> #REF! | AA36: =IF($L36="","",SUMIF(#REF!,$L36,#REF!)) -> #REF! | AB36: =IF($L36="","",SUMIF(#REF!,$L36,#REF!)) -> #REF! | AD36: =IF($L36="","",SUMIF(#REF!,$L36,#REF!)) -> #REF! | AE36: =IF($L36="","",SUMIF(#REF!,$L36,#REF!)) -> #REF! | AG36: =IF($L36="","",SUMIF(#REF!,$L36,#REF!)) -> #REF!
A37: Christian Johnston | B37: Technical Support Rep | C37: Technical Support | D37: {=IFERROR(_xlfn.TEXTJOIN(", ",TRUE,_xlfn.UNIQUE(_xlfn._xlws.FILTER(#REF!,(#REF!="Final")*(COUNTIFS('[1]Demand Capacity'!$B:$B,$A37,'[1]Demand Capacity'!$A:$A,#REF!)>0),""))),"")} | E37: Crystal Ross | F37: FTE | G37: Stratus | H37: Indiana | I37: Support | J37: Other | K37: Mid | M37: =IF($L37="","",SUMIF(#REF!,$L37,#REF!)) | O37: =IF($L37="","",SUMIF(#REF!,$L37,#REF!)) | P37: =IF($L37="","",SUMIF(#REF!,$L37,#REF!)) | R37: =IF($L37="","",SUMIF(#REF!,$L37,#REF!)) | S37: =IF($L37="","",SUMIF(#REF!,$L37,#REF!)) | U37: =IF($L37="","",SUMIF(#REF!,$L37,#REF!)) | V37: =IF($L37="","",SUMIF(#REF!,$L37,#REF!)) | X37: =IF($L37="","",SUMIF(#REF!,$L37,#REF!)) | Y37: =IF($L37="","",SUMIF(#REF!,$L37,#REF!)) | AA37: =IF($L37="","",SUMIF(#REF!,$L37,#REF!)) | AB37: =IF($L37="","",SUMIF(#REF!,$L37,#REF!)) | AD37: =IF($L37="","",SUMIF(#REF!,$L37,#REF!)) | AE37: =IF($L37="","",SUMIF(#REF!,$L37,#REF!)) | AG37: =IF($L37="","",SUMIF(#REF!,$L37,#REF!))
A38: Skylar Ryals | B38: Technical Support Rep | C38: Technical Support | D38: {=IFERROR(_xlfn.TEXTJOIN(", ",TRUE,_xlfn.UNIQUE(_xlfn._xlws.FILTER(#REF!,(#REF!="Final")*(COUNTIFS('[1]Demand Capacity'!$B:$B,$A38,'[1]Demand Capacity'!$A:$A,#REF!)>0),""))),"")} | E38: Crystal Ross | F38: FTE | G38: Stratus | H38: New Mexico | I38: Support | J38: Other | K38: Mid | L38: S-Ryals | M38: =IF($L38="","",SUMIF(#REF!,$L38,#REF!)) -> #REF! | O38: =IF($L38="","",SUMIF(#REF!,$L38,#REF!)) -> #REF! | P38: =IF($L38="","",SUMIF(#REF!,$L38,#REF!)) -> #REF! | R38: =IF($L38="","",SUMIF(#REF!,$L38,#REF!)) -> #REF! | S38: =IF($L38="","",SUMIF(#REF!,$L38,#REF!)) -> #REF! | U38: =IF($L38="","",SUMIF(#REF!,$L38,#REF!)) -> #REF! | V38: =IF($L38="","",SUMIF(#REF!,$L38,#REF!)) -> #REF! | X38: =IF($L38="","",SUMIF(#REF!,$L38,#REF!)) -> #REF! | Y38: =IF($L38="","",SUMIF(#REF!,$L38,#REF!)) -> #REF! | AA38: =IF($L38="","",SUMIF(#REF!,$L38,#REF!)) -> #REF! | AB38: =IF($L38="","",SUMIF(#REF!,$L38,#REF!)) -> #REF! | AD38: =IF($L38="","",SUMIF(#REF!,$L38,#REF!)) -> #REF! | AE38: =IF($L38="","",SUMIF(#REF!,$L38,#REF!)) -> #REF! | AG38: =IF($L38="","",SUMIF(#REF!,$L38,#REF!)) -> #REF!
A39: Jonah Sly | B39: Technical Support Rep | C39: Technical Support | D39: {=IFERROR(_xlfn.TEXTJOIN(", ",TRUE,_xlfn.UNIQUE(_xlfn._xlws.FILTER(#REF!,(#REF!="Final")*(COUNTIFS('[1]Demand Capacity'!$B:$B,$A39,'[1]Demand Capacity'!$A:$A,#REF!)>0),""))),"")} | E39: Crystal Ross | F39: FTE | G39: Stratus | H39: Texas | I39: Support | J39: Other | K39: Mid | M39: =IF($L39="","",SUMIF(#REF!,$L39,#REF!)) | O39: =IF($L39="","",SUMIF(#REF!,$L39,#REF!)) | P39: =IF($L39="","",SUMIF(#REF!,$L39,#REF!)) | R39: =IF($L39="","",SUMIF(#REF!,$L39,#REF!)) | S39: =IF($L39="","",SUMIF(#REF!,$L39,#REF!)) | U39: =IF($L39="","",SUMIF(#REF!,$L39,#REF!)) | V39: =IF($L39="","",SUMIF(#REF!,$L39,#REF!)) | X39: =IF($L39="","",SUMIF(#REF!,$L39,#REF!)) | Y39: =IF($L39="","",SUMIF(#REF!,$L39,#REF!)) | AA39: =IF($L39="","",SUMIF(#REF!,$L39,#REF!)) | AB39: =IF($L39="","",SUMIF(#REF!,$L39,#REF!)) | AD39: =IF($L39="","",SUMIF(#REF!,$L39,#REF!)) | AE39: =IF($L39="","",SUMIF(#REF!,$L39,#REF!)) | AG39: =IF($L39="","",SUMIF(#REF!,$L39,#REF!))
L40: DavidU-GTP | M40: =IF($L40="","",SUMIF(#REF!,$L40,#REF!)) -> #REF! | O40: =IF($L40="","",SUMIF(#REF!,$L40,#REF!)) -> #REF! | P40: =IF($L40="","",SUMIF(#REF!,$L40,#REF!)) -> #REF! | R40: =IF($L40="","",SUMIF(#REF!,$L40,#REF!)) -> #REF! | S40: =IF($L40="","",SUMIF(#REF!,$L40,#REF!)) -> #REF! | U40: =IF($L40="","",SUMIF(#REF!,$L40,#REF!)) -> #REF! | V40: =IF($L40="","",SUMIF(#REF!,$L40,#REF!)) -> #REF! | X40: =IF($L40="","",SUMIF(#REF!,$L40,#REF!)) -> #REF! | Y40: =IF($L40="","",SUMIF(#REF!,$L40,#REF!)) -> #REF! | AA40: =IF($L40="","",SUMIF(#REF!,$L40,#REF!)) -> #REF! | AB40: =IF($L40="","",SUMIF(#REF!,$L40,#REF!)) -> #REF! | AD40: =IF($L40="","",SUMIF(#REF!,$L40,#REF!)) -> #REF! | AE40: =IF($L40="","",SUMIF(#REF!,$L40,#REF!)) -> #REF! | AG40: =IF($L40="","",SUMIF(#REF!,$L40,#REF!)) -> #REF!
...

Sheet Data
A1: Full Name | B1: Title | C1: Team | D1: Workstream | E1: Manager | F1: Employment Type | G1: Company | H1: Location | I1: Discipline | J1: Role | K1: Seniority | L1: GitHub Account | M1: May 1–8 | P1: May 8–15 | S1: May 15–22 | V1: May 22–29 | Y1: May 29–Jun 5 | AB1: Jun 5–10 | AE1: Total | AH1: Notes
M2: PR | N2: Tickets | O2: LoC | P2: PR | Q2: Tickets | R2: LoC | S2: PR | T2: Tickets | U2: LoC | V2: PR | W2: Tickets | X2: LoC | Y2: PR | Z2: Tickets | AA2: LoC | AB2: PR | AC2: Tickets | AD2: LoC | AE2: PR | AF2: Tickets | AG2: LoC
A3: Anthony Anderson | B3: Interim Director of Engineering | C3: Engineering Leadership | D3: Admin | E3: Annu Singh | F3: FTE | G3: Stratus | H3: Orlando | I3: Leadership | J3: Other | K3: Director | L3: anthonyagtp | M3: 3 | N3: 1 | O3: 102 | P3: 0 | Q3: 0 | R3: 0 | S3: 0 | T3: 0 | U3: 0 | V3: 0 | W3: 3 | X3: 485 | Y3: 0 | Z3: 2 | AA3: 485 | AB3: 0 | AC3: 0 | AD3: 457 | AE3: 3 | AF3: 6 | AG3: 1529
A4: Asa Baylus | B4: VP Engineering | C4: Engineering Leadership | D4: Admin | E4: Annu Singh | F4: FTE | G4: Stratus | H4: Virginia | I4: Leadership | J4: Other | K4: Director | L4: asabaylus | M4: 0 | N4: 1 | O4: 7017 | P4: 3 | Q4: 1 | R4: 7045 | S4: 4 | T4: 0 | U4: 5249 | V4: 0 | W4: 1 | X4: 1033 | Y4: 0 | Z4: 0 | AA4: 9196 | AB4: 2 | AC4: 0 | AD4: 20951 | AE4: 9 | AF4: 3 | AG4: 50491
A5: Jonathan Umscheid | B5: Chief Innovation Officer | C5: Engineering Leadership | D5: Admin | E5: Annu Singh | F5: FTE | G5: Stratus | H5: North Carolina | I5: Leadership | J5: Other | K5: Director | L5: jonathanumscheid | M5: 0 | N5: 0 | O5: 0 | P5: 1 | Q5: 0 | R5: 20 | S5: 1 | T5: 0 | U5: 20 | V5: 1 | W5: 0 | X5: 5119 | Y5: 5 | Z5: 2 | AA5: 23561 | AB5: 1 | AC5: 3 | AD5: 4873 | AE5: 9 | AF5: 5 | AG5: 33593
A6: Crystal Ross | B6: Director Technical Support | C6: Engineering Leadership | D6: Admin | E6: Annu Singh | F6: FTE | G6: Stratus | H6: Massachusetts | I6: Leadership | J6: Other | K6: Director | N6: 0 | Q6: 1 | T6: 0 | W6: 0 | Z6: 0 | AC6: 0 | AF6: 1
A7: Chris Bown | B7: Senior Director, Platform Engineering | C7: Engineering Leadership | D7: Admin | E7: Annu Singh | F7: FTE | G7: Stratus | H7: Phoenix | I7: Leadership | J7: Developer | K7: Director | L7: cbown75 | M7: 99 | N7: 85 | O7: 86186 | P7: 30 | Q7: 34 | R7: 16786 | S7: 11 | T7: 13 | U7: 5433 | V7: 10 | W7: 7 | X7: 3716 | Y7: 17 | Z7: 13 | AA7: 1415 | AB7: 11 | AC7: 16 | AD7: 3262 | AE7: 178 | AF7: 168 | AG7: 116798
A8: Andy Robins | B8: Full Stack Engineer | C8: Labs | D8: {=IFERROR(_xlfn.TEXTJOIN(", ",TRUE,_xlfn.UNIQUE(_xlfn._xlws.FILTER(#REF!,(#REF!="Final")*(COUNTIFS('[1]Demand Capacity'!$B:$B,$A8,'[1]Demand Capacity'!$A:$A,#REF!)>0),""))),"")} | E8: Jonathan Umscheid | F8: FTE | G8: Stratus | H8: UK | I8: Full Stack | J8: Developer | K8: Lead | L8: andyrobins-gtp | M8: 0 | N8: 0 | O8: 0 | P8: 0 | Q8: 0 | R8: 0 | S8: 0 | T8: 0 | U8: 0 | V8: 0 | W8: 0 | X8: 0 | Y8: 0 | Z8: 0 | AA8: 3418 | AB8: 0 | AC8: 0 | AD8: 0 | AE8: 0 | AF8: 0 | AG8: 3418
A9: Don Porter | B9: Full Stack Engineer | C9: Labs | D9: {=IFERROR(_xlfn.TEXTJOIN(", ",TRUE,_xlfn.UNIQUE(_xlfn._xlws.FILTER(#REF!,(#REF!="Final")*(COUNTIFS('[1]Demand Capacity'!$B:$B,$A9,'[1]Demand Capacity'!$A:$A,#REF!)>0),""))),"")} | E9: Jonathan Umscheid | F9: FTE | G9: Stratus | H9: Columbia | I9: Full Stack | J9: Developer | K9: Senior | L9: donatgtp | M9: 0 | N9: 0 | O9: 13569 | P9: 0 | Q9: 1 | R9: 120146 | S9: 0 | T9: 0 | U9: 12105 | V9: 0 | W9: 0 | X9: 16062 | Y9: 0 | Z9: 1 | AA9: 24899 | AB9: 0 | AC9: 0 | AD9: 11427 | AE9: 0 | AF9: 2 | AG9: 198208
A10: Francisco Micucci | B10: Full Stack Engineer | C10: Labs | D10: {=IFERROR(_xlfn.TEXTJOIN(", ",TRUE,_xlfn.UNIQUE(_xlfn._xlws.FILTER(#REF!,(#REF!="Final")*(COUNTIFS('[1]Demand Capacity'!$B:$B,$A10,'[1]Demand Capacity'!$A:$A,#REF!)>0),""))),"")} | E10: Asa Baylus | F10: Contractor | G10: Marvik | I10: Full Stack | J10: Developer | K10: Senior | L10: famicucci | M10: 7 | N10: 8 | O10: 4504 | P10: 5 | Q10: 4 | R10: 7510 | S10: 9 | T10: 5 | U10: 8061 | V10: 3 | W10: 4 | X10: 7460 | Y10: 9 | Z10: 3 | AA10: 8710 | AB10: 6 | AC10: 6 | AD10: 1262 | AE10: 39 | AF10: 30 | AG10: 37507
A11: Eric Spieguel | B11: Data Engineer | C11: Labs | D11: {=IFERROR(_xlfn.TEXTJOIN(", ",TRUE,_xlfn.UNIQUE(_xlfn._xlws.FILTER(#REF!,(#REF!="Final")*(COUNTIFS('[1]Demand Capacity'!$B:$B,$A11,'[1]Demand Capacity'!$A:$A,#REF!)>0),""))),"")} | E11: Asa Baylus | F11: Contractor | G11: Marvik | I11: DS | J11: Developer | K11: Senior | L11: ericspiguel | M11: 0 | N11: 0 | O11: 0 | P11: 0 | Q11: 0 | R11: 0 | S11: 0 | T11: 0 | U11: 0 | V11: 0 | W11: 0 | X11: 9088 | Y11: 1 | Z11: 2 | AA11: 9088 | AB11: 0 | AC11: 2 | AD11: 0 | AE11: 1 | AF11: 4 | AG11: 18176
A12: Juan Oliu | B12: Architect / Lead | C12: Labs | D12: {=IFERROR(_xlfn.TEXTJOIN(", ",TRUE,_xlfn.UNIQUE(_xlfn._xlws.FILTER(#REF!,(#REF!="Final")*(COUNTIFS('[1]Demand Capacity'!$B:$B,$A12,'[1]Demand Capacity'!$A:$A,#REF!)>0),""))),"")} | E12: Asa Baylus | F12: Contractor | G12: Marvik | I12: Full Stack | J12: Developer | K12: Lead | L12: jmoliugp | M12: 0 | N12: 1 | O12: 0 | P12: 12 | Q12: 5 | R12: 54480 | S12: 6 | T12: 9 | U12: 1158508 | V12: 1 | W12: 2 | X12: 6381 | Y12: 2 | Z12: 2 | AA12: 27556 | AB12: 1 | AC12: 0 | AD12: 14844 | AE12: 22 | AF12: 19 | AG12: 1261769
A13: Aaron Entwistle | B13: Senior Platform Engineer | C13: Platform | D13: {=IFERROR(_xlfn.TEXTJOIN(", ",TRUE,_xlfn.UNIQUE(_xlfn._xlws.FILTER(#REF!,(#REF!="Final")*(COUNTIFS('[1]Demand Capacity'!$B:$B,$A13,'[1]Demand Capacity'!$A:$A,#REF!)>0),""))),"")} | E13: Chris Bown | F13: FTE | G13: Stratus | H13: Phoenix | I13: DevOps | J13: Developer | K13: Senior | L13: aaronentwistle | M13: 8 | N13: 1 | O13: 1244 | P13: 7 | Q13: 14 | R13: 1233 | S13: 15 | T13: 13 | U13: 2536 | V13: 15 | W13: 3 | X13: 1478 | Y13: 6 | Z13: 1 | AA13: 1316 | AB13: 13 | AC13: 11 | AD13: 4601 | AE13: 64 | AF13: 43 | AG13: 12408
A14: Anisah Reed | B14: Platform Engineer | C14: Platform | D14: {=IFERROR(_xlfn.TEXTJOIN(", ",TRUE,_xlfn.UNIQUE(_xlfn._xlws.FILTER(#REF!,(#REF!="Final")*(COUNTIFS('[1]Demand Capacity'!$B:$B,$A14,'[1]Demand Capacity'!$A:$A,#REF!)>0),""))),"")} | E14: Chris Bown | F14: Contractor | G14: Stratus | H14: Houston | I14: DevOps | J14: Developer | K14: Mid | L14: AnisahReed | M14: 0 | N14: 0 | O14: 0 | P14: 2 | Q14: 1 | R14: 85 | S14: 0 | T14: 0 | U14: 456 | V14: 2 | W14: 0 | X14: 1037 | Y14: 1 | Z14: 0 | AA14: 1799 | AB14: 0 | AC14: 0 | AD14: 2628 | AE14: 5 | AF14: 1 | AG14: 6005
A15: Zach Ward | B15: Platform Engineer | C15: Platform | D15: {=IFERROR(_xlfn.TEXTJOIN(", ",TRUE,_xlfn.UNIQUE(_xlfn._xlws.FILTER(#REF!,(#REF!="Final")*(COUNTIFS('[1]Demand Capacity'!$B:$B,$A15,'[1]Demand Capacity'!$A:$A,#REF!)>0),""))),"")} | E15: Chris Bown | F15: FTE | G15: Stratus | H15: San Diego | I15: DevOps | J15: Developer | K15: Mid | L15: zwardstratus | M15: 8 | N15: 9 | O15: 1566 | P15: 34 | Q15: 1 | R15: 4277 | S15: 22 | T15: 13 | U15: 1699 | V15: 11 | W15: 4 | X15: 1161 | Y15: 12 | Z15: 12 | AA15: 2142 | AB15: 13 | AC15: 13 | AD15: 1776 | AE15: 100 | AF15: 52 | AG15: 12621
A16: Kyle Snyder | B16: IT (Platform team) | C16: Platform | D16: {=IFERROR(_xlfn.TEXTJOIN(", ",TRUE,_xlfn.UNIQUE(_xlfn._xlws.FILTER(#REF!,(#REF!="Final")*(COUNTIFS('[1]Demand Capacity'!$B:$B,$A16,'[1]Demand Capacity'!$A:$A,#REF!)>0),""))),"")} | E16: Chris Bown | F16: FTE | G16: Stratus | H16: Kansas City | I16: IT | J16: Other | K16: Mid | L16: kylesnydergogtp | M16: 0 | N16: 0 | O16: 0 | P16: 0 | Q16: 0 | R16: 0 | S16: 0 | T16: 0 | U16: 0 | V16: 1 | W16: 1 | X16: 34 | Y16: 2 | Z16: 0 | AA16: 39 | AB16: 2 | AC16: 1 | AD16: 38 | AE16: 5 | AF16: 2 | AG16: 111
